Workbook
Name dram_access_latency: Architecture!$B$4
Name dram_bandwidth: Architecture!$B$3
Name frequency: Architecture!$B$2
Name ic_unroll: Architecture!$B$5
Name oc_unroll: Architecture!$B$6

Sheet Architecture
A1: Architecture (editable)
A2: frequency | B2: 1
A3: dram_bandwidth | B3: 68
A4: dram_access_latency | B4: 100
A5: ic_unroll | B5: 64
A6: oc_unroll | B6: 64
A8: bytes/cycle | B8: =dram_bandwidth/frequency -> 68

Sheet Operations
A1: Node | B1: Op type | C1: Input | D1: Weight | E1: Output | F1: Macs / Ops | G1: Ideal cycles | H1: Utilization | I1: Effective cycles
A2: quantize_default | B2: vector | C2: 1x1x4096 | E2: 1x1x4096 | F2: 4096 | G2: =CEILING(F2/oc_unroll,1) -> 64 | H2: 0.5 | I2: =CEILING(G2/H2,1) -> 128
A3: model_layers_0_input_layernorm_fused | B3: vector | C3: 1x1x4096 | E3: 1x1x4096 | F3: 4096 | G3: =CEILING(F3/oc_unroll,1) -> 64 | H3: 0.03125 | I3: =CEILING(G3/H3,1) -> 2048
A4: model_layers_0_self_attn_q_proj_fused | B4: gemm | C4: 1x1x4096 | D4: 1024x4096 | E4: 1x1x1024 | F4: 4194304 | G4: =CEILING(F4/oc_unroll,1) -> 65536 | H4: 1 | I4: =CEILING(G4/H4,1) -> 65536
A5: model_layers_0_self_attn_k_proj_fused | B5: gemm | C5: 1x1x4096 | D5: 1024x4096 | E5: 1x1x1024 | F5: 4194304 | G5: =CEILING(F5/oc_unroll,1) -> 65536 | H5: 1 | I5: =CEILING(G5/H5,1) -> 65536
A6: model_layers_0_self_attn_v_proj_fused | B6: gemm | C6: 1x1x4096 | D6: 1024x4096 | E6: 1x1x1024 | F6: 4194304 | G6: =CEILING(F6/oc_unroll,1) -> 65536 | H6: 1 | I6: =CEILING(G6/H6,1) -> 65536
A7: neg | B7: vector | C7: 1x32x1x64 | E7: 1x32x1x64 | F7: 2048 | G7: =CEILING(F7/oc_unroll,1) -> 32 | H7: 0.5 | I7: =CEILING(G7/H7,1) -> 64
A8: mul_3 | B8: vector | C8: 1x32x1x128 | E8: 1x32x1x128 | F8: 4096 | G8: =CEILING(F8/oc_unroll,1) -> 64 | H8: 0.5 | I8: =CEILING(G8/H8,1) -> 128
A9: mul_2_fused | B9: vector | C9: 1x32x1x128 | E9: 1x32x1x128 | F9: 4096 | G9: =CEILING(F9/oc_unroll,1) -> 64 | H9: 0.5 | I9: =CEILING(G9/H9,1) -> 128
A10: neg_1 | B10: vector | C10: 1x32x1x64 | E10: 1x32x1x64 | F10: 2048 | G10: =CEILING(F10/oc_unroll,1) -> 32 | H10: 0.5 | I10: =CEILING(G10/H10,1) -> 64
A11: mul_5 | B11: vector | C11: 1x32x1x128 | E11: 1x32x1x128 | F11: 4096 | G11: =CEILING(F11/oc_unroll,1) -> 64 | H11: 0.5 | I11: =CEILING(G11/H11,1) -> 128
A12: mul_4_fused | B12: vector | C12: 1x32x1x128 | E12: 1x32x1x128 | F12: 4096 | G12: =CEILING(F12/oc_unroll,1) -> 64 | H12: 0.5 | I12: =CEILING(G12/H12,1) -> 128
A13: quantize_mx_default_3 | B13: vector | C13: 1x2x128x640 | E13: 1x2x128x640 | F13: 163840 | G13: =CEILING(F13/oc_unroll,1) -> 2560 | H13: 0.5 | I13: =CEILING(G13/H13,1) -> 5120
A14: matmul_mx_default_fused | B14: gemm | C14: 1x1x1x128 | D14: 1x1x640x128 | E14: 1x1x1x640 | F14: 81920 | G14: =CEILING(F14/oc_unroll,1) -> 1280 | H14: 1 | I14: =CEILING(G14/H14,1) -> 1280
A15: softmax_fused | B15: vector | C15: 1x8x1x640 | E15: 1x8x1x640 | F15: 5120 | G15: =CEILING(F15/oc_unroll,1) -> 80 | H15: 0.16666667 | I15: =CEILING(G15/H15,1) -> 480
A16: sub_32 | B16: vector | C16: 1 | E16: 1 | F16: 1 | G16: =CEILING(F16/oc_unroll,1) -> 1 | H16: 0.125 | I16: =CEILING(G16/H16,1) -> 8
A17: quantize_mx_3 | B17: vector | C17: 1x4x128x128 | E17: 1x4x128x128 | F17: 65536 | G17: =CEILING(F17/oc_unroll,1) -> 1024 | H17: 0.5 | I17: =CEILING(G17/H17,1) -> 2048
A18: matmul_mx_1 | B18: gemm | C18: 1x1x1x128 | D18: 1x1x128x128 | E18: 1x1x1x128 | F18: 16384 | G18: =CEILING(F18/oc_unroll,1) -> 256 | H18: 1 | I18: =CEILING(G18/H18,1) -> 256
A19: matmul_mx_fused | B19: gemm | C19: 1x1x1x512 | D19: 1x1x128x512 | E19: 1x1x1x128 | F19: 65536 | G19: =CEILING(F19/oc_unroll,1) -> 1024 | H19: 1 | I19: =CEILING(G19/H19,1) -> 1024
A20: model_layers_0_self_attn_o_proj_fused | B20: gemm | C20: 1x1x4096 | D20: 1024x4096 | E20: 1x1x1024 | F20: 4194304 | G20: =CEILING(F20/oc_unroll,1) -> 65536 | H20: 1 | I20: =CEILING(G20/H20,1) -> 65536
A21: quantize_default_3 | B21: vector | C21: 1x1x4096 | E21: 1x1x4096 | F21: 4096 | G21: =CEILING(F21/oc_unroll,1) -> 64 | H21: 0.5 | I21: =CEILING(G21/H21,1) -> 128
A22: model_layers_0_post_attention_layernorm_fused | B22: vector | C22: 1x1x4096 | E22: 1x1x4096 | F22: 4096 | G22: =CEILING(F22/oc_unroll,1) -> 64 | H22: 0.03125 | I22: =CEILING(G22/H22,1) -> 2048
A23: model_layers_0_mlp_gate_proj_fused | B23: gemm | C23: 1x1x4096 | D23: 256x4096 | E23: 1x1x256 | F23: 1048576 | G23: =CEILING(F23/oc_unroll,1) -> 16384 | H23: 1 | I23: =CEILING(G23/H23,1) -> 16384
A24: model_layers_0_mlp_up_proj_fused | B24: gemm | C24: 1x1x4096 | D24: 256x4096 | E24: 1x1x256 | F24: 1048576 | G24: =CEILING(F24/oc_unroll,1) -> 16384 | H24: 1 | I24: =CEILING(G24/H24,1) -> 16384
A25: model_layers_0_mlp_down_proj_fused | B25: gemm | C25: 1x1x11008 | D25: 256x11008 | E25: 1x1x256 | F25: 2818048 | G25: =CEILING(F25/oc_unroll,1) -> 44032 | H25: 1 | I25: =CEILING(G25/H25,1) -> 44032
A26: lm_head | B26: gemm | C26: 1x4096 | D26: 640x4096 | E26: 1x640 | F26: 2621440 | G26: =CEILING(F26/oc_unroll,1) -> 40960 | H26: 1 | I26: =CEILING(G26/H26,1) -> 40960

Sheet Events
A1: EID | B1: Node | C1: Kind | D1: Resource | E1: Iter | F1: Bytes | G1: Start | H1: Latency | I1: End | J1: Compute | K1: DRAM | L1: Read B | M1: Write B
A2: 0 | B2: async_copy_35 | C2: load | D2: dram | E2: () | F2: 8192 | G2: =0 -> 0 | H2: =CEILING((dram_access_latency+F2/dram_bandwidth)*frequency,1) -> 221 | I2: =G2+H2 -> 221 | J2: =IF(AND(D2<>"dram",D2<>"control"),H2,0) -> 0 | K2: =IF(D2="dram",H2,0) -> 221 | L2: 8192 | M2: 0
A3: 1 | B3: async_wait_11 | C3: async_wait | D3: control | E3: (0,) | F3: 0 | G3: =MAX(I2) -> 0 | H3: =0 -> 221 | I3: =G3+H3 -> 221 | J3: =IF(AND(D3<>"dram",D3<>"control"),H3,0) -> 0 | K3: =IF(D3="dram",H3,0) -> 0 | L3: 0 | M3: 0
A4: 2 | B4: quantize_default | C4: compute | D4: vector | E4: (0,) | F4: 0 | G4: =MAX(I3) -> 221 | H4: ='Operations'!I2 -> 128 | I4: =G4+H4 -> 349 | J4: =IF(AND(D4<>"dram",D4<>"control"),H4,0) -> 128 | K4: =IF(D4="dram",H4,0) -> 0 | L4: 0 | M4: 0
A5: 3 | B5: async_copy_37 | C5: store | D5: dram | E5: (0,) | F5: 4096 | G5: =MAX(I4,I2) -> 349 | H5: =CEILING((dram_access_latency+F5/dram_bandwidth)*frequency,1) -> 161 | I5: =G5+H5 -> 510 | J5: =IF(AND(D5<>"dram",D5<>"control"),H5,0) -> 0 | K5: =IF(D5="dram",H5,0) -> 161 | L5: 0 | M5: 4096
A6: 4 | B6: async_wait_13 | C6: async_wait | D6: control | E6: () | F6: 0 | G6: =MAX(I4,I5) -> 349 | H6: =0 -> 161 | I6: =G6+H6 -> 510 | J6: =IF(AND(D6<>"dram",D6<>"control"),H6,0) -> 0 | K6: =IF(D6="dram",H6,0) -> 0 | L6: 0 | M6: 0
A7: 5 | B7: async_copy_38 | C7: load | D7: dram | E7: () | F7: 4096 | G7: =MAX(I6,I5) -> 510 | H7: =CEILING((dram_access_latency+F7/dram_bandwidth)*frequency,1) -> 161 | I7: =G7+H7 -> 671 | J7: =IF(AND(D7<>"dram",D7<>"control"),H7,0) -> 0 | K7: =IF(D7="dram",H7,0) -> 161 | L7: 4096 | M7: 0
A8: 6 | B8: async_copy_39 | C8: load | D8: dram | E8: () | F8: 8192 | G8: =MAX(I6,I7) -> 671 | H8: =CEILING((dram_access_latency+F8/dram_bandwidth)*frequency,1) -> 221 | I8: =G8+H8 -> 892 | J8: =IF(AND(D8<>"dram",D8<>"control"),H8,0) -> 0 | K8: =IF(D8="dram",H8,0) -> 221 | L8: 8192 | M8: 0
A9: 7 | B9: async_wait_15 | C9: async_wait | D9: control | E9: (0,) | F9: 0 | G9: =MAX(I6,I7) -> 510 | H9: =0 -> 161 | I9: =G9+H9 -> 671 | J9: =IF(AND(D9<>"dram",D9<>"control"),H9,0) -> 0 | K9: =IF(D9="dram",H9,0) -> 0 | L9: 0 | M9: 0
A10: 8 | B10: async_wait_16 | C10: async_wait | D10: control | E10: (0,) | F10: 0 | G10: =MAX(I9,I8) -> 671 | H10: =0 -> 221 | I10: =G10+H10 -> 892 | J10: =IF(AND(D10<>"dram",D10<>"control"),H10,0) -> 0 | K10: =IF(D10="dram",H10,0) -> 0 | L10: 0 | M10: 0
A11: 9 | B11: model_layers_0_input_layernorm_fused | C11: compute | D11: vector | E11: (0,) | F11: 0 | G11: =MAX(I10,I4) -> 892 | H11: ='Operations'!I3 -> 2048 | I11: =G11+H11 -> 2940 | J11: =IF(AND(D11<>"dram",D11<>"control"),H11,0) -> 2048 | K11: =IF(D11="dram",H11,0) -> 0 | L11: 0 | M11: 0
A12: 10 | B12: async_copy_42 | C12: store | D12: dram | E12: (0,) | F12: 64 | G12: =MAX(I11,I8) -> 2940 | H12: =CEILING((dram_access_latency+F12/dram_bandwidth)*frequency,1) -> 101 | I12: =G12+H12 -> 3041 | J12: =IF(AND(D12<>"dram",D12<>"control"),H12,0) -> 0 | K12: =IF(D12="dram",H12,0) -> 101 | L12: 0 | M12: 64
A13: 11 | B13: async_copy_43 | C13: store | D13: dram | E13: (0,) | F13: 2048 | G13: =MAX(I11,I12) -> 3041 | H13: =CEILING((dram_access_latency+F13/dram_bandwidth)*frequency,1) -> 131 | I13: =G13+H13 -> 3172 | J13: =IF(AND(D13<>"dram",D13<>"control"),H13,0) -> 0 | K13: =IF(D13="dram",H13,0) -> 131 | L13: 0 | M13: 2048
A14: 12 | B14: async_wait_19 | C14: async_wait | D14: control | E14: () | F14: 0 | G14: =MAX(I11,I12) -> 2940 | H14: =0 -> 101 | I14: =G14+H14 -> 3041 | J14: =IF(AND(D14<>"dram",D14<>"control"),H14,0) -> 0 | K14: =IF(D14="dram",H14,0) -> 0 | L14: 0 | M14: 0
A15: 13 | B15: async_wait_21 | C15: async_wait | D15: control | E15: () | F15: 0 | G15: =MAX(I14,I13) -> 3041 | H15: =0 -> 131 | I15: =G15+H15 -> 3172 | J15: =IF(AND(D15<>"dram",D15<>"control"),H15,0) -> 0 | K15: =IF(D15="dram",H15,0) -> 0 | L15: 0 | M15: 0
A16: 14 | B16: async_copy_44 | C16: load | D16: dram | E16: (0,) | F16: 2048 | G16: =MAX(I15,I13) -> 3172 | H16: =CEILING((dram_access_latency+F16/dram_bandwidth)*frequency,1) -> 131 | I16: =G16+H16 -> 3303 | J16: =IF(AND(D16<>"dram",D16<>"control"),H16,0) -> 0 | K16: =IF(D16="dram",H16,0) -> 131 | L16: 2048 | M16: 0
A17: 15 | B17: async_copy_45 | C17: load | D17: dram | E17: (0,) | F17: 2097152 | G17: =MAX(I15,I16) -> 3303 | H17: =CEILING((dram_access_latency+F17/dram_bandwidth)*frequency,1) -> 30941 | I17: =G17+H17 -> 34244 | J17: =IF(AND(D17<>"dram",D17<>"control"),H17,0) -> 0 | K17: =IF(D17="dram",H17,0) -> 30941 | L17: 2097152 | M17: 0
A18: 16 | B18: async_copy_46 | C18: load | D18: dram | E18: (0,) | F18: 64 | G18: =MAX(I15,I17) -> 34244 | H18: =CEILING((dram_access_latency+F18/dram_bandwidth)*frequency,1) -> 101 | I18: =G18+H18 -> 34345 | J18: =IF(AND(D18<>"dram",D18<>"control"),H18,0) -> 0 | K18: =IF(D18="dram",H18,0) -> 101 | L18: 64 | M18: 0
A19: 17 | B19: async_copy_47 | C19: load | D19: dram | E19: (0,) | F19: 65536 | G19: =MAX(I15,I18) -> 34345 | H19: =CEILING((dram_access_latency+F19/dram_bandwidth)*frequency,1) -> 1064 | I19: =G19+H19 -> 35409 | J19: =IF(AND(D19<>"dram",D19<>"control"),H19,0) -> 0 | K19: =IF(D19="dram",H19,0) -> 1064 | L19: 65536 | M19: 0
A20: 18 | B20: model_layers_0_self_attn_q_proj_fused | C20: compute | D20: vector | E20: (0,) | F20: 0 | G20: =MAX(I11,I16,I17,I18,I19) -> 35409 | H20: ='Operations'!I4 -> 65536 | I20: =G20+H20 -> 100945 | J20: =IF(AND(D20<>"dram",D20<>"control"),H20,0) -> 65536 | K20: =IF(D20="dram",H20,0) -> 0 | L20: 0 | M20: 0
A21: 19 | B21: async_copy_45 | C21: load | D21: dram | E21: (1,) | F21: 2097152 | G21: =MAX(I15,I19) -> 35409 | H21: =CEILING((dram_access_latency+F21/dram_bandwidth)*frequency,1) -> 30941 | I21: =G21+H21 -> 66350 | J21: =IF(AND(D21<>"dram",D21<>"control"),H21,0) -> 0 | K21: =IF(D21="dram",H21,0) -> 30941 | L21: 2097152 | M21: 0
A22: 20 | B22: async_copy_47 | C22: load | D22: dram | E22: (1,) | F22: 65536 | G22: =MAX(I15,I21) -> 66350 | H22: =CEILING((dram_access_latency+F22/dram_bandwidth)*frequency,1) -> 1064 | I22: =G22+H22 -> 67414 | J22: =IF(AND(D22<>"dram",D22<>"control"),H22,0) -> 0 | K22: =IF(D22="dram",H22,0) -> 1064 | L22: 65536 | M22: 0
A23: 21 | B23: model_layers_0_self_attn_q_proj_fused | C23: compute | D23: vector | E23: (1,) | F23: 0 | G23: =MAX(I20,I16,I21,I18,I22) -> 100945 | H23: ='Operations'!I4 -> 65536 | I23: =G23+H23 -> 166481 | J23: =IF(AND(D23<>"dram",D23<>"control"),H23,0) -> 65536 | K23: =IF(D23="dram",H23,0) -> 0 | L23: 0 | M23: 0
A24: 22 | B24: async_wait_23 | C24: async_wait | D24: control | E24: (1,) | F24: 0 | G24: =MAX(I15,I20) -> 3172 | H24: =0 -> 97773 | I24: =G24+H24 -> 100945 | J24: =IF(AND(D24<>"dram",D24<>"control"),H24,0) -> 0 | K24: =IF(D24="dram",H24,0) -> 0 | L24: 0 | M24: 0
A25: 23 | B25: async_copy_48 | C25: store | D25: dram | E25: (1,) | F25: 2048 | G25: =MAX(I24,I22) -> 100945 | H25: =CEILING((dram_access_latency+F25/dram_bandwidth)*frequency,1) -> 131 | I25: =G25+H25 -> 101076 | J25: =IF(AND(D25<>"dram",D25<>"control"),H25,0) -> 0 | K25: =IF(D25="dram",H25,0) -> 131 | L25: 0 | M25: 2048
A26: 24 | B26: async_copy_45 | C26: load | D26: dram | E26: (2,) | F26: 2097152 | G26: =MAX(I24,I25) -> 101076 | H26: =CEILING((dram_access_latency+F26/dram_bandwidth)*frequency,1) -> 30941 | I26: =G26+H26 -> 132017 | J26: =IF(AND(D26<>"dram",D26<>"control"),H26,0) -> 0 | K26: =IF(D26="dram",H26,0) -> 30941 | L26: 2097152 | M26: 0
A27: 25 | B27: async_copy_47 | C27: load | D27: dram | E27: (2,) | F27: 65536 | G27: =MAX(I24,I26) -> 132017 | H27: =CEILING((dram_access_latency+F27/dram_bandwidth)*frequency,1) -> 1064 | I27: =G27+H27 -> 133081 | J27: =IF(AND(D27<>"dram",D27<>"control"),H27,0) -> 0 | K27: =IF(D27="dram",H27,0) -> 1064 | L27: 65536 | M27: 0
A28: 26 | B28: model_layers_0_self_attn_q_proj_fused | C28: compute | D28: vector | E28: (2,) | F28: 0 | G28: =MAX(I23,I16,I26,I18,I27,I25) -> 166481 | H28: ='Operations'!I4 -> 65536 | I28: =G28+H28 -> 232017 | J28: =IF(AND(D28<>"dram",D28<>"control"),H28,0) -> 65536 | K28: =IF(D28="dram",H28,0) -> 0 | L28: 0 | M28: 0
A29: 27 | B29: async_wait_23 | C29: async_wait | D29: control | E29: (2,) | F29: 0 | G29: =MAX(I24,I23) -> 100945 | H29: =0 -> 65536 | I29: =G29+H29 -> 166481 | J29: =IF(AND(D29<>"dram",D29<>"control"),H29,0) -> 0 | K29: =IF(D29="dram",H29,0) -> 0 | L29: 0 | M29: 0
A30: 28 | B30: async_copy_48 | C30: store | D30: dram | E30: (2,) | F30: 2048 | G30: =MAX(I29,I27) -> 166481 | H30: =CEILING((dram_access_latency+F30/dram_bandwidth)*frequency,1) -> 131 | I30: =G30+H30 -> 166612 | J30: =IF(AND(D30<>"dram",D30<>"control"),H30,0) -> 0 | K30: =IF(D30="dram",H30,0) -> 131 | L30: 0 | M30: 2048
A31: 29 | B31: async_copy_45 | C31: load | D31: dram | E31: (3,) | F31: 2097152 | G31: =MAX(I29,I30) -> 166612 | H31: =CEILING((dram_access_latency+F31/dram_bandwidth)*frequency,1) -> 30941 | I31: =G31+H31 -> 197553 | J31: =IF(AND(D31<>"dram",D31<>"control"),H31,0) -> 0 | K31: =IF(D31="dram",H31,0) -> 30941 | L31: 2097152 | M31: 0
A32: 30 | B32: async_copy_47 | C32: load | D32: dram | E32: (3,) | F32: 65536 | G32: =MAX(I29,I31) -> 197553 | H32: =CEILING((dram_access_latency+F32/dram_bandwidth)*frequency,1) -> 1064 | I32: =G32+H32 -> 198617 | J32: =IF(AND(D32<>"dram",D32<>"control"),H32,0) -> 0 | K32: =IF(D32="dram",H32,0) -> 1064 | L32: 65536 | M32: 0
A33: 31 | B33: model_layers_0_self_attn_q_proj_fused | C33: compute | D33: vector | E33: (3,) | F33: 0 | G33: =MAX(I28,I16,I31,I18,I32,I30) -> 232017 | H33: ='Operations'!I4 -> 65536 | I33: =G33+H33 -> 297553 | J33: =IF(AND(D33<>"dram",D33<>"control"),H33,0) -> 65536 | K33: =IF(D33="dram",H33,0) -> 0 | L33: 0 | M33: 0
A34: 32 | B34: async_wait_23 | C34: async_wait | D34: control | E34: (3,) | F34: 0 | G34: =MAX(I29,I28) -> 166481 | H34: =0 -> 65536 | I34: =G34+H34 -> 232017 | J34: =IF(AND(D34<>"dram",D34<>"control"),H34,0) -> 0 | K34: =IF(D34="dram",H34,0) -> 0 | L34: 0 | M34: 0
A35: 33 | B35: async_copy_48 | C35: store | D35: dram | E35: (3,) | F35: 2048 | G35: =MAX(I34,I32) -> 232017 | H35: =CEILING((dram_access_latency+F35/dram_bandwidth)*frequency,1) -> 131 | I35: =G35+H35 -> 232148 | J35: =IF(AND(D35<>"dram",D35<>"control"),H35,0) -> 0 | K35: =IF(D35="dram",H35,0) -> 131 | L35: 0 | M35: 2048
A36: 34 | B36: async_wait_24 | C36: async_wait | D36: control | E36: () | F36: 0 | G36: =MAX(I34,I33) -> 232017 | H36: =0 -> 65536 | I36: =G36+H36 -> 297553 | J36: =IF(AND(D36<>"dram",D36<>"control"),H36,0) -> 0 | K36: =IF(D36="dram",H36,0) -> 0 | L36: 0 | M36: 0
A37: 35 | B37: async_copy_49 | C37: store | D37: dram | E37: () | F37: 2048 | G37: =MAX(I36,I35) -> 297553 | H37: =CEILING((dram_access_latency+F37/dram_bandwidth)*frequency,1) -> 131 | I37: =G37+H37 -> 297684 | J37: =IF(AND(D37<>"dram",D37<>"control"),H37,0) -> 0 | K37: =IF(D37="dram",H37,0) -> 131 | L37: 0 | M37: 2048
A38: 36 | B38: async_wait_25 | C38: async_wait | D38: control | E38: () | F38: 0 | G38: =MAX(I36,I35) -> 297553 | H38: =0 -> 0 | I38: =G38+H38 -> 297553 | J38: =IF(AND(D38<>"dram",D38<>"control"),H38,0) -> 0 | K38: =IF(D38="dram",H38,0) -> 0 | L38: 0 | M38: 0
A39: 37 | B39: async_wait_26 | C39: async_wait | D39: control | E39: () | F39: 0 | G39: =MAX(I38,I37) -> 297553 | H39: =0 -> 131 | I39: =G39+H39 -> 297684 | J39: =IF(AND(D39<>"dram",D39<>"control"),H39,0) -> 0 | K39: =IF(D39="dram",H39,0) -> 0 | L39: 0 | M39: 0
A40: 38 | B40: async_copy_50 | C40: load | D40: dram | E40: (0,) | F40: 2048 | G40: =MAX(I39,I37) -> 297684 | H40: =CEILING((dram_access_latency+F40/dram_bandwidth)*frequency,1) -> 131 | I40: =G40+H40 -> 297815 | J40: =IF(AND(D40<>"dram",D40<>"control"),H40,0) -> 0 | K40: =IF(D40="dram",H40,0) -> 131 | L40: 2048 | M40: 0
...

Sheet Gantt

Sheet Period

Sheet Summary
A1: Totals
A2: total_latency | B2: =MAX(Events!I2:I2053) -> 5887604
A3: dram_read_bytes | B3: =SUM(Events!L2:L2053) -> 189760780
A4: dram_write_bytes | B4: =SUM(Events!M2:M2053) -> 9945588
A6: Loops (compressed)
A7: Loop | B7: Trip | C7: Period iters events | D7: Repeat | E7: Period cyc | F7: Compact
A8: while_loop_25 | B8: 1 | C8: 0 | D8: 1 | E8: 510 | F8: prefix + period x 1 + suffix
A9: while_loop_26 | B9: 1 | C9: 0 | D9: 1 | E9: 2662 | F9: prefix + period x 1 + suffix
A10: while_loop_27 | B10: 4 | C10: 0 | D10: 2 | E10: 65536 | F10: prefix + period x 2 + suffix
A11: while_loop_28 | B11: 4 | C11: 0 | D11: 2 | E11: 65536 | F11: prefix + period x 2 + suffix
A12: while_loop_29 | B12: 4 | C12: 0 | D12: 2 | E12: 65536 | F12: prefix + period x 2 + suffix
A13: while_loop_30 | B13: 1 | C13: 0 | D13: 1 | E13: 386 | F13: prefix + period x 1 + suffix
A14: while_loop_31 | B14: 1 | C14: 0 | D14: 1 | E14: 674 | F14: prefix + period x 1 + suffix
A15: while_loop_32 | B15: 1 | C15: 0 | D15: 1 | E15: 921 | F15: prefix + period x 1 + suffix
A16: while_loop_33 | B16: 1 | C16: 0 | D16: 1 | E16: 386 | F16: prefix + period x 1 + suffix
A17: while_loop_34 | B17: 1 | C17: 0 | D17: 1 | E17: 674 | F17: prefix + period x 1 + suffix
A18: while_loop_35 | B18: 1 | C18: 0 | D18: 1 | E18: 895 | F18: prefix + period x 1 + suffix
A19: while_loop_36 | B19: 16 | C19: 7 | D19: 13 | E19: 6965 | F19: prefix + period x 13 + suffix
... A32: while_loop_49 | B32: 50 | C32: 5 | D32: 48 | E32: 40960 | F32: prefix + period x 48 + suffix
